<?xml version = "1.0"?>
<!-- the xmlns:xacro part is required for the xacro to run properly -->
<robot name = "dd_robot" xmlns:xacro="http://www.ros.org/wiki/xacro">

  <xacro:include filename="$(find ros_robotics)/urdf/materials.xacro" />
  <xacro:include filename="$(find ros_robotics)/urdf/gazebo.xacro" />
  <xacro:include filename="$(find ros_robotics)/urdf/macros.xacro" />
  
  <!-- Base link description -->
  <!-- Differently from the sdf standard, the arguments are usually quoted -->
  <link name = "base_link">

	<visual>
	  <origin xyz = "0 0 0" rpy = "0 0 0 " />
	  <geometry>
		<box size = ".4 .2 .1" />
	  </geometry>
	  <material name="blue"/>
	</visual>

	<!-- Chassis collision -->
	<collision>
	  <!-- <origin xyz="0 0 0" rpy="0 0 0"/> -->
	  <geometry>
		<box size=".4 .2 .1"/>
	  </geometry>
	</collision>

	<!-- Inertial properties of the chassis -->
	<inertial>
	  <mass value="10"/>
	  <origin xyz="0.0 0 0.1" rpy = "0 0 0" />
	  <!-- <inertia ixx="0.13" ixy="0.0" ixz="0.0" -->
	  <!-- 		   iyy="0.29" iyz="0.0" izz="0.371"/> -->
	  <inertia ixx = "0.042" ixy = "0.0" ixz = "0.0"
	  		   iyy = "0.142" iyz = "0.0" izz = "0.167"/>
	</inertial>

	<!-- Front Caster -->
	<!-- The caster is inside of the base link. I couldn't create it a link because
		 it would need a joint to attach it to the base link -->
	<visual name="caster">
	  <origin xyz=".15 0 -0.05" rpy="0 0 0"/>
	  <geometry>
		<sphere radius="0.05"/>
	  </geometry>
	  <material name="blue"/>
	</visual>

	<!-- Caster collision -->
	<collision name='caster_collision'>
	  <origin xyz="0.15 0 -0.05" rpy="0 0 0"/>
	  <geometry>
		<sphere radius="0.05"/>
	  </geometry>
	  <surface>
		<friction>
		  <ode>
			<mu>0</mu>
			<mu2>0</mu2>
			<slip1>1.0</slip1>
			<slip2>1.0</slip2>
		  </ode>
		</friction>
	  </surface>
	</collision>
	
	<inertial>
	  <mass value="0.5"/>
	  <inertia ixx="0.0001" ixy="0.0" ixz="0.0"
			   iyy="0.0001" iyz="0.0" izz="0.0001"/>
	</inertial>

  </link>


  <link name="laser_scanner">
	<visual>
	  <origin xyz="0 0 0" rpy="0 0 0"/>
	  <geometry>
		<cylinder length="0.05" radius="0.05"/>
	  </geometry>
	  <material name="black"/>
	</visual>

	<xacro:cylinder_inertia_z_axis mass="0.5" r="0.05" l="0.05"/>

	<collision>
	  <origin xyz="0 0 0" rpy="0 0 0"/>
	  <geometry>
		<cylinder length="0.05" radius="0.05"/>
	  </geometry>
	</collision>
  </link>

  <joint name="laser_scanner_joint" type="continuous">
	<parent link="base_link"/>
	<child link="laser_scanner"/>
	<origin xyz="0.0 0.0 0.05" rpy="0 0 0"/>
	<axis xyz="0 0 1"/>
  </joint>

  <!-- Right wheel -->
  <xacro:link_wheel name="right_wheel"/>
  <xacro:joint_wheel name="right" child="right_wheel" x="-0.1" y="-0.15" z="0.0"/>
  
  <!-- Left wheel -->
  <xacro:link_wheel name="left_wheel"/>
  <xacro:joint_wheel name="left" child="left_wheel" x="-0.1" y="0.15" z="0.0"/>

</robot>
