<?xml version="1.0"?>
<robot xmlns:xacro="http://www.ros.org/wiki/xacro">

  <!-- The origin of the wheel needs to be the same as the one for the base link
		for easier desiging of the robot -->
  <xacro:macro name="link_wheel" params="name">
	<!-- Generic wheel -->
	<link name="${name}">
	  <visual>
		<origin xyz="0 0 0" rpy="1.570795 0 0" />
		<geometry>
		  <cylinder length="0.1" radius="0.2" />
		</geometry>
		<material name="black"/>
	  </visual>

	  <!-- Generic wheel collision -->
	  <collision>
		<origin xyz="0 0 0" rpy="1.570795 0 0"/>
		<geometry>
		  <cylinder length="0.1" radius="0.2"/>
		</geometry>
	  </collision>

	  <!-- Generic wheel inertial model -->
	  <inertial>
		<mass value="0.5"/>
		<inertia ixx="0.01" ixy="0.0" ixz="0.0"
				 iyy="0.005" iyz="0.0" izz="0.005"/>
	  </inertial>

	</link>
  </xacro:macro>

  <!-- The joint origin is defined in regards to the base_link reference (in this case, "0 0 0");
		hence, the origin of the wheel attached to it indicates, from the origin of the join, where
		the wheel will be drawn. To check this out, change the wheel's origin to 0.3 and leave the 
		joint origin as is.-->


  <xacro:macro name="joint_wheel" params="name child x y z">
	<joint name="${name}_joint_wheel" type="continuous">
	  <parent link="base_link"/>
	  <child link="${child}"/>
	  <origin xyz="${x} ${y} ${z}" rpy="0 0 0" />
	  <axis xyz="0 1 0"/>
	</joint>
  </xacro:macro>

  <!-- https://en.wikipedia.org/wiki/List_of_moments_of_inertia#List_of_3D_inertia_tensors -->
  <xacro:macro name="cylinder_inertia" params="mass r l">
	<inertia ixx="${mass * (3 * r * r + l * l) / 12}" ixy="0.0" ixz="0.0"
			 iyy="${mass * (3 * r * r + l * l) / 12}" iyz="0.0"
			 izz="${mass *  (r * r) / 2}"/>
  </xacro:macro>
</robot>
